// a promise is an object which will get executed later on as a promise
// as we know we use new keyword to initialize an object

const promiseOne = new Promise(function(resolve, reject){
    //Do an async task
    // DB calls, cryptography, network
    setTimeout(function(){
        console.log('Async task is compelete');
        resolve()
    }, 1000)
})

promiseOne.then(function(){
    console.log("Promise consumed");
})

new Promise(function(resolve, reject){
    setTimeout(function(){
        console.log("Async task 2");
        resolve()
    }, 1000)

}).then(function(){
    console.log("Async 2 resolved");
})

const promiseThree = new Promise(function(resolve, reject){
    setTimeout(function(){
        resolve({username: "Chai", email: "chai@example.com"})
    }, 1000)
})

promiseThree.then(function(user){
    console.log(user);
})

const promiseFour = new Promise(function(resolve, reject){
    setTimeout(function(){
        let error = false
        if (!error) {
            resolve({username: "hitesh", password: "123"})
        } else {
            reject('ERROR: Something went wrong')
        }
    }, 1000)
})

 promiseFour
 .then((user) => {
    console.log(user);
    return user.username
}).then((username) => {
    console.log(username);
}).catch(function(error){
    console.log(error);
}).finally(() => console.log("The promise is either resolved or rejected"))
// chaining it is called


const promiseFive = new Promise(function(resolve, reject){
    setTimeout(function(){
        let error = false
        if (!error) {
            resolve({username: "javascript", password: "123"})
        } else {
            reject('ERROR: JS went wrong')
        }
    }, 1000)
});

async function consumePromiseFive(){
    try {
        const response = await promiseFive
        console.log(response);
    } catch (error) {
        console.log(error);
    }
}

consumePromiseFive()

// async function getAllUsers(){
//     try {
//         const response = await fetch('https://jsonplaceholder.typicode.com/users')

//         const data = await response.json()
//         console.log(data);
//     } catch (error) {
//         console.log("E: ", error);
//     }
// }

//getAllUsers()

// async function is used mainly in database connections
fetch('https://api.github.com/users/hiteshchoudhary')
.then((response) => {
    return response.json()
})
.then((data) => {
    console.log(data);
})
.catch((error) => console.log(error))

// promise.all
// yes this is also available, kuch reading aap b kro.

// two syntax for promise i.e 
// async and then catch finally
// resolve is used to consume a promise


// When we run all the promise code we see that the hitesh github code api comes first and then all our data of other promises comes 
// what is the reason

// fetch came recently in 2022 before that we used to use xmlhhtprequest
// all developers were happy with its introduction 
// fetch is process of fetching a resource 
// common question asked in sde interviews is that if we get an error 404 in promise where it'll go resolve or reject
// answer is that we will get it in response
// we get error only if the request is not made 
